2024-08-13 00:45:06,856:WARNING: * Debugger is active!
2024-08-13 01:14:18,150:WARNING: * Debugger is active!
2024-08-13 01:19:12,821:WARNING: * Debugger is active!
2024-08-13 01:23:43,665:WARNING: * Debugger is active!
2024-08-13 01:24:41,511:WARNING: * Debugger is active!
2024-08-13 01:42:14,489:WARNING: * Debugger is active!
2024-08-13 01:47:10,130:WARNING: * Debugger is active!
2024-08-13 01:47:42,667:WARNING: * Debugger is active!
2024-08-13 02:09:01,490:WARNING: * Debugger is active!
2024-08-13 02:10:28,058:WARNING: * Debugger is active!
2024-08-13 02:10:51,252:WARNING: * Debugger is active!
2024-08-13 02:11:12,677:WARNING: * Debugger is active!
2024-08-13 02:13:47,937:WARNING: * Debugger is active!
2024-08-13 02:17:43,357:WARNING: * Debugger is active!
2024-08-13 12:53:45,606:ERROR:Exception during reset or similar
Traceback (most recent call last):
  File "/Users/lucian/Desktop/Github/ASPJ24/aspj24/lib/python3.11/site-packages/sqlalchemy/pool/base.py", line 988, in _finalize_fairy
    fairy._reset(
  File "/Users/lucian/Desktop/Github/ASPJ24/aspj24/lib/python3.11/site-packages/sqlalchemy/pool/base.py", line 1438, in _reset
    pool._dialect.do_rollback(self)
  File "/Users/lucian/Desktop/Github/ASPJ24/aspj24/lib/python3.11/site-packages/sqlalchemy/engine/default.py", line 692, in do_rollback
    dbapi_connection.rollback()
  File "/Users/lucian/Desktop/Github/ASPJ24/aspj24/lib/python3.11/site-packages/pymysql/connections.py", line 493, in rollback
    self._read_ok_packet()
  File "/Users/lucian/Desktop/Github/ASPJ24/aspj24/lib/python3.11/site-packages/pymysql/connections.py", line 453, in _read_ok_packet
    pkt = self._read_packet()
          ^^^^^^^^^^^^^^^^^^^
  File "/Users/lucian/Desktop/Github/ASPJ24/aspj24/lib/python3.11/site-packages/pymysql/connections.py", line 744, in _read_packet
    packet_header = self._read_bytes(4)
                    ^^^^^^^^^^^^^^^^^^^
  File "/Users/lucian/Desktop/Github/ASPJ24/aspj24/lib/python3.11/site-packages/pymysql/connections.py", line 798, in _read_bytes
    raise err.OperationalError(
pymysql.err.OperationalError: (2013, 'Lost connection to MySQL server during query')
2024-08-13 12:58:28,743:WARNING: * Debugger is active!
2024-08-13 13:03:29,309:WARNING: * Debugger is active!
2024-08-13 13:05:04,366:WARNING: * Debugger is active!
2024-08-13 13:06:47,636:ORDER:Order 1 completed by 90288065
2024-08-13 13:07:45,331:WARNING: * Debugger is active!
2024-08-13 13:08:27,424:WARNING: * Debugger is active!
2024-08-13 13:09:44,834:WARNING: * Debugger is active!
